Workbook

Sheet Shrnutí
B1: Teplota ČR od roku 1961
B2: adresa | C2: verze | D2: autor | E2: licence
B3: https://faktaoklimatu.cz/infografiky/teplota-cr https://faktaoklimatu.cz/infografiky/teplota-cr-mesice https://faktaoklimatu.cz/infografiky/trend-teplot-cr | C3: 45662 | D3: Fakta o klimatu | E3: CC BY 4.0
B4: =IF(ISERR(FIND("neaktuální", C2)), "", "Toto je neaktuální verze datasetu. Aktuální verzi naleznete na stránce výše.")
B5: Historie změn
B6: 45662 | C6: Aktualizace průměrných teplot za rok 2024 podle dat z tiskové zprávy ČHMÚ
B7: 45295 | C7: Aktualizace průměrných teplot za rok 2023 podle dat z tiskové zprávy ČHMÚ
B8: 45162 | C8: Aktualizace průměrných teplot za rok 2022 podle dat ČHMÚ
B9: 43904 | C9: Aktualizace průměrných teplot za rok 2021 podle dat ČHMÚ
B10: 44572 | C10: Aktualizace za rok 2021
B11: 44254 | C11: Aktualizace za rok 2020
B12: 43866 | C12: První verze datasetu
A14: A | B14: VSTUPY
B15: Údaj | C15: Zdroj | D15: Hodnota | E15: Datum stažení | F15: Komentář | I15: Odkaz
A17: 1 | B17: Měsíční teploty v ČR
B18: Měsíční teploty v ČR | C18: ČHMÚ | D18: Tabulka v příloze | E18: 45662 | F18: Data ručně vykopírována z jednotlivých let. Na zdrojových stránkách jsou v odkazech pro jednotlivé roky uvedené průměrné teploty vzduchu [°C] v daném měsíci, uspořádané podle měsíců (v daném roce) a podle krajů. Vzhledem k velikosti ČR nebudou v trendech pro jednotlivé kraje podstatné rozdíly, proto dále pracujeme pouze s průměrnými teplotami pro daný rok a měsíc v rámci celé ČR. | I18: http://portal.chmi.cz/historicka-data/pocasi/uzemni-teploty
A20: B | B20: VÝSTUPY
A22: 3 | B22: Lineární trend
B23: Sklon lineárního trendu teplot ČR | D23: {=TRANSPOSE(LINEST('Vstup Měsíční teploty ČR'!N4:N67))} -> 0.036771978 | F23: Spočítáno metodou nejmenších čtverců.
B24: Hodnota lineárního trendu teplot ČR pro první rok (1961) | D24: 6.7330357 | F24: Spočítáno metodou nejmenších čtverců.
A26: 4 | B26: Průměrné roční teploty v ČR
B28: Rok | C28: Průměrná teplota | D28: Klouzavý průměr 5 let | E28: Lineární trend
B29: ='Vstup Měsíční teploty ČR'!$A4 -> 1961 | C29: ='Vstup Měsíční teploty ČR'!$N4 -> 7.9 | D29: není k dispozici | E29: =$D$24+$D$23*($B29-1961) -> 6.7330357
B30: ='Vstup Měsíční teploty ČR'!A5 -> 1962 | C30: ='Vstup Měsíční teploty ČR'!$N5 -> 6.3 | D30: není k dispozici | E30: =$D$24+$D$23*($B30-1961) -> 6.7698077
B31: ='Vstup Měsíční teploty ČR'!A6 -> 1963 | C31: ='Vstup Měsíční teploty ČR'!$N6 -> 6.5 | D31: =AVERAGE(C29:C33) -> 6.8 | E31: =$D$24+$D$23*($B31-1961) -> 6.8065797
B32: ='Vstup Měsíční teploty ČR'!A7 -> 1964 | C32: ='Vstup Měsíční teploty ČR'!$N7 -> 6.9 | D32: =AVERAGE(C30:C34) -> 6.8 | E32: =$D$24+$D$23*($B32-1961) -> 6.8433516
B33: ='Vstup Měsíční teploty ČR'!A8 -> 1965 | C33: ='Vstup Měsíční teploty ČR'!$N8 -> 6.4 | D33: =AVERAGE(C31:C35) -> 7.14 | E33: =$D$24+$D$23*($B33-1961) -> 6.8801236
B34: ='Vstup Měsíční teploty ČR'!A9 -> 1966 | C34: ='Vstup Měsíční teploty ČR'!$N9 -> 7.9 | D34: =AVERAGE(C32:C36) -> 7.3 | E34: =$D$24+$D$23*($B34-1961) -> 6.9168956
B35: ='Vstup Měsíční teploty ČR'!A10 -> 1967 | C35: ='Vstup Měsíční teploty ČR'!$N10 -> 8 | D35: =AVERAGE(C33:C37) -> 7.3 | E35: =$D$24+$D$23*($B35-1961) -> 6.9536676
B36: ='Vstup Měsíční teploty ČR'!A11 -> 1968 | C36: ='Vstup Měsíční teploty ČR'!$N11 -> 7.3 | D36: =AVERAGE(C34:C38) -> 7.4 | E36: =$D$24+$D$23*($B36-1961) -> 6.9904396
B37: ='Vstup Měsíční teploty ČR'!A12 -> 1969 | C37: ='Vstup Měsíční teploty ČR'!$N12 -> 6.9 | D37: =AVERAGE(C35:C39) -> 7.32 | E37: =$D$24+$D$23*($B37-1961) -> 7.0272115
B38: ='Vstup Měsíční teploty ČR'!A13 -> 1970 | C38: ='Vstup Měsíční teploty ČR'!$N13 -> 6.9 | D38: =AVERAGE(C36:C40) -> 7.16 | E38: =$D$24+$D$23*($B38-1961) -> 7.0639835
B39: ='Vstup Měsíční teploty ČR'!A14 -> 1971 | C39: ='Vstup Měsíční teploty ČR'!$N14 -> 7.5 | D39: =AVERAGE(C37:C41) -> 7.14 | E39: =$D$24+$D$23*($B39-1961) -> 7.1007555
B40: ='Vstup Měsíční teploty ČR'!A15 -> 1972 | C40: ='Vstup Měsíční teploty ČR'!$N15 -> 7.2 | D40: =AVERAGE(C38:C42) -> 7.34 | E40: =$D$24+$D$23*($B40-1961) -> 7.1375275
B41: ='Vstup Měsíční teploty ČR'!A16 -> 1973 | C41: ='Vstup Měsíční teploty ČR'!$N16 -> 7.2 | D41: =AVERAGE(C39:C43) -> 7.56 | E41: =$D$24+$D$23*($B41-1961) -> 7.1742995
B42: ='Vstup Měsíční teploty ČR'!A17 -> 1974 | C42: ='Vstup Měsíční teploty ČR'!$N17 -> 7.9 | D42: =AVERAGE(C40:C44) -> 7.52 | E42: =$D$24+$D$23*($B42-1961) -> 7.2110714
... B87: ='Vstup Měsíční teploty ČR'!A62 -> 2019 | C87: ='Vstup Měsíční teploty ČR'!$N62 -> 9.5 | D87: =AVERAGE(C85:C89) -> 8.96 | E87: =$D$24+$D$23*($B87-1961) -> 8.8658104
B88: 2020 | C88: ='Vstup Měsíční teploty ČR'!$N63 -> 9.1 | D88: =AVERAGE(C86:C90) -> 9.08 | E88: =$D$24+$D$23*($B88-1961) -> 8.9025824
B89: 2021 | C89: ='Vstup Měsíční teploty ČR'!$N64 -> 8 | D89: =AVERAGE(C87:C91) -> 9.1 | E89: =$D$24+$D$23*($B89-1961) -> 8.9393544
B90: 2022 | C90: ='Vstup Měsíční teploty ČR'!$N65 -> 9.2 | D90: =AVERAGE(C88:C92) -> 9.26 | E90: =$D$24+$D$23*($B90-1961) -> 8.9761264
...

Sheet Vstup Měsíční teploty ČR
A1: Zdroj | B1: Komentář
A2: ='Shrnutí'!I18 -> http://portal.chmi.cz/historicka-data/pocasi/uzemni-teploty | B2: ='Shrnutí'!F18 -> Data ručně vykopírována z jednotlivých let. Na zdrojových stránkách jsou v odkazech pro jednotlivé roky uvedené průměrné teploty vzduchu [°C] v daném měsíci, uspořádané podle měsíců (v daném roce) a podle krajů. Vzhledem k velikosti ČR nebudou v trendech pro jednotlivé kraje podstatné rozdíly, proto dále pracujeme pouze s průměrnými teplotami pro daný rok a měsíc v rámci celé ČR.
A3: Rok | B3: Leden | C3: Únor | D3: Březen | E3: Duben | F3: Květen | G3: Červen | H3: Červenec | I3: Srpen | J3: Září | K3: Říjen | L3: Listopad | M3: Prosinec | N3: Roční průměr
A4: 1961 | B4: -3.4 | C4: 1.7 | D4: 5.1 | E4: 10.7 | F4: 10.2 | G4: 16.2 | H4: 15.2 | I4: 15.7 | J4: 15 | K4: 9.4 | L4: 2.7 | M4: -3.2 | N4: 7.9
A5: =A4+1 -> 1962 | B5: -1.2 | C5: -2.1 | D5: -1.1 | E5: 8.6 | F5: 9.7 | G5: 13.8 | H5: 15.1 | I5: 16.7 | J5: 11.8 | K5: 7.5 | L5: 2.4 | M5: -5.5 | N5: 6.3
A6: =A5+1 -> 1963 | B6: -8.9 | C6: -6.9 | D6: 0.6 | E6: 8.1 | F6: 12 | G6: 16 | H6: 18 | I6: 16.5 | J6: 13.8 | K6: 7.4 | L6: 6.4 | M6: -5.6 | N6: 6.5
A7: =A6+1 -> 1964 | B7: -5.9 | C7: -2.3 | D7: -1.2 | E7: 8.3 | F7: 12.8 | G7: 17.5 | H7: 17.8 | I7: 15.1 | J7: 12.6 | K7: 6.7 | L7: 3.7 | M7: -1.7 | N7: 6.9
A8: =A7+1 -> 1965 | B8: -0.8 | C8: -4.7 | D8: 0.7 | E8: 6.1 | F8: 10.2 | G8: 15.2 | H8: 15.5 | I8: 14.7 | J8: 12.7 | K8: 6.5 | L8: -0.3 | M8: 0.7 | N8: 6.4
A9: =A8+1 -> 1966 | B9: -5.4 | C9: 3.7 | D9: 2.2 | E9: 9.1 | F9: 12.4 | G9: 16.2 | H9: 15.9 | I9: 15.3 | J9: 12.4 | K9: 11.3 | L9: 1.8 | M9: -0.1 | N9: 7.9
A10: =A9+1 -> 1967 | B10: -2.5 | C10: 0.4 | D10: 4.1 | E10: 6.5 | F10: 12.6 | G10: 15 | H10: 18.5 | I10: 16.2 | J10: 13.8 | K10: 10.3 | L10: 2.6 | M10: -1.5 | N10: 8
A11: =A10+1 -> 1968 | B11: -3.7 | C11: -0.2 | D11: 3.3 | E11: 8.5 | F11: 11.2 | G11: 16.2 | H11: 16.1 | I11: 15.7 | J11: 12.6 | K11: 8.4 | L11: 3.4 | M11: -3.7 | N11: 7.3
A12: =A11+1 -> 1969 | B12: -2.9 | C12: -2.9 | D12: -0.4 | E12: 6.7 | F12: 14.2 | G12: 14.8 | H12: 17.9 | I12: 15.5 | J12: 13.1 | K12: 8.8 | L12: 4.2 | M12: -6.3 | N12: 6.9
A13: =A12+1 -> 1970 | B13: -3.9 | C13: -2.7 | D13: 0.3 | E13: 5.7 | F13: 10.6 | G13: 16.3 | H13: 16.7 | I13: 16.3 | J13: 11.9 | K13: 7.4 | L13: 4.7 | M13: -1.1 | N13: 6.9
A14: =A13+1 -> 1971 | B14: -3.6 | C14: -0.2 | D14: -0.3 | E14: 8 | F14: 13.7 | G14: 13.8 | H14: 17.7 | I14: 18.4 | J14: 10.7 | K14: 7.1 | L14: 2.1 | M14: 2.1 | N14: 7.5
A15: =A14+1 -> 1972 | B15: -3.9 | C15: 1 | D15: 4.6 | E15: 6.7 | F15: 11.7 | G15: 15.5 | H15: 17.8 | I15: 15.7 | J15: 10.2 | K15: 5.3 | L15: 3.2 | M15: -1.3 | N15: 7.2
A16: =A15+1 -> 1973 | B16: -1.8 | C16: -0.2 | D16: 3.1 | E16: 4.9 | F16: 12.3 | G16: 15.3 | H16: 16.6 | I16: 17.1 | J16: 13.7 | K16: 6 | L16: 1.1 | M16: -1.5 | N16: 7.2
... A62: =A61+1 -> 2019 | B62: -1.7 | C62: 1.7 | D62: 5.6 | E62: 9.4 | F62: 10.7 | G62: 20.7 | H62: 18.8 | I62: 18.9 | J62: 13.3 | K62: 9.5 | L62: 5.6 | M62: 1.9 | N62: 9.5
A63: 2020 | B63: 0.3 | C63: 3.7 | D63: 3.9 | E63: 9.2 | F63: 10.9 | G63: 16.4 | H63: 17.7 | I63: 18.8 | J63: 14 | K63: 9 | L63: 3.9 | M63: 1.7 | N63: 9.1
A64: 2021 | B64: -1.1 | C64: 0.8 | D64: 2.6 | E64: 5.4 | F64: 10.6 | G64: 18.8 | H64: 18.8 | I64: 16 | J64: 14.2 | K64: 8 | L64: 3.6 | M64: 0.4 | N64: 8
A65: 2022 | B65: 0.6 | C65: 2.8 | D65: 3.1 | E65: 6.4 | F65: 14.3 | G65: 18.7 | H65: 18.6 | I65: 19.1 | J65: 12 | K65: 10.7 | L65: 4.1 | M65: 0.3 | N65: 9.2
A66: 2023 | B66: 2 | C66: 1.2 | D66: 4.7 | E66: 6.4 | F66: 12.6 | G66: 17.2 | H66: 19.6 | I66: 18.6 | J66: 16.5 | K66: 11.1 | L66: 4.1 | M66: =12*N66-sum(B66:L66) -> 2.4 | N66: 9.7
A67: 2024 | B67: -0.5 | C67: 5.7 | D67: 7 | E67: 10 | F67: 14.5 | G67: 17.9 | H67: 19.8 | I67: 20.2 | J67: 15 | K67: 9.8 | L67: 2.8 | M67: 0.9 | N67: 10.3

Sheet Výstup Teploty ČR podle měsíců
A1: {=TRANSPOSE('Vstup Měsíční teploty ČR'!A3:N67)} -> Rok | B1: 1961 | C1: 1962 | D1: 1963 | E1: 1964 | F1: 1965 | G1: 1966 | H1: 1967 | I1: 1968 | J1: 1969 | K1: 1970 | L1: 1971 | M1: 1972 | N1: 1973 | O1: 1974 | P1: 1975 | Q1: 1976 | R1: 1977 | S1: 1978 | T1: 1979 | U1: 1980 | V1: 1981 | W1: 1982 | X1: 1983 | Y1: 1984 | Z1: 1985 | AA1: 1986 | AB1: 1987 | AC1: 1988 | AD1: 1989 | AE1: 1990 | AF1: 1991 | AG1: 1992 | AH1: 1993 | AI1: 1994 | AJ1: 1995 | AK1: 1996 | AL1: 1997 | AM1: 1998 | AN1: 1999 | AO1: 2000 | AP1: 2001 | AQ1: 2002 | AR1: 2003 | AS1: 2004 | AT1: 2005 | AU1: 2006 | AV1: 2007 | AW1: 2008 | AX1: 2009 | AY1: 2010 | AZ1: 2011 | BA1: 2012 | BB1: 2013 | BC1: 2014 | BD1: 2015 | BE1: 2016 | BF1: 2017 | BG1: 2018 | BH1: 2019 | BI1: 2020 | BJ1: 2021 | BK1: 2022 | BL1: 2023 | BM1: 2024
A2: Leden | B2: -3.4 | C2: -1.2 | D2: -8.9 | E2: -5.9 | F2: -0.8 | G2: -5.4 | H2: -2.5 | I2: -3.7 | J2: -2.9 | K2: -3.9 | L2: -3.6 | M2: -3.9 | N2: -1.8 | O2: 0.8 | P2: 2 | Q2: -1.1 | R2: -1.8 | S2: -1 | T2: -5.8 | U2: -5.1 | V2: -4.1 | W2: -5.4 | X2: 2.2 | Y2: -1.2 | Z2: -7.9 | AA2: -1.7 | AB2: -8.1 | AC2: 1.2 | AD2: -0.3 | AE2: -0.4 | AF2: -0.4 | AG2: -0.3 | AH2: -0.2 | AI2: 1.6 | AJ2: -2 | AK2: -4.7 | AL2: -4.5 | AM2: 0.1 | AN2: -0.4 | AO2: -2.4 | AP2: -1.6 | AQ2: -1.3 | AR2: -2.4 | AS2: -3.9 | AT2: -0.4 | AU2: -6 | AV2: 3.1 | AW2: 1.3 | AX2: -4 | AY2: -5 | AZ2: -1.2 | BA2: -0.2 | BB2: -1.9 | BC2: 0.5 | BD2: 0.9 | BE2: -1.4 | BF2: -5.6 | BG2: 1.8 | BH2: -1.7 | BI2: 0.3 | BJ2: -1.1 | BK2: 0.6 | BL2: 2 | BM2: -0.5
A3: Únor | B3: 1.7 | C3: -2.1 | D3: -6.9 | E3: -2.3 | F3: -4.7 | G3: 3.7 | H3: 0.4 | I3: -0.2 | J3: -2.9 | K3: -2.7 | L3: -0.2 | M3: 1 | N3: -0.2 | O3: 2.3 | P3: -1.1 | Q3: -1.2 | R3: 0.8 | S3: -3.1 | T3: -2 | U3: 0.5 | V3: -1.5 | W3: -2.4 | X3: -3.5 | Y3: -1.8 | Z3: -5.8 | AA3: -7.8 | AB3: -1.8 | AC3: 0.6 | AD3: 2.2 | AE3: 3.4 | AF3: -4.6 | AG3: 1.2 | AH3: -3 | AI3: -1.3 | AJ3: 3.1 | AK3: -4.8 | AL3: 1.4 | AM3: 2.6 | AN3: -1.7 | AO3: 2.1 | AP3: 0.3 | AQ3: 3.4 | AR3: -4.4 | AS3: 0.4 | AT3: -3.7 | AU3: -3 | AV3: 2.8 | AW3: 2.3 | AX3: -1 | AY3: -1.8 | AZ3: -2 | BA3: -5.2 | BB3: -1.4 | BC3: 2.1 | BD3: -0.1 | BE3: 3 | BF3: 1.1 | BG3: -3.5 | BH3: 1.7 | BI3: 3.7 | BJ3: 0.8 | BK3: 2.8 | BL3: 1.2 | BM3: 5.7
A4: Březen | B4: 5.1 | C4: -1.1 | D4: 0.6 | E4: -1.2 | F4: 0.7 | G4: 2.2 | H4: 4.1 | I4: 3.3 | J4: -0.4 | K4: 0.3 | L4: -0.3 | M4: 4.6 | N4: 3.1 | O4: 5.6 | P4: 3.2 | Q4: -0.5 | R4: 5.4 | S4: 3.7 | T4: 3.3 | U4: 1.7 | V4: 5.8 | W4: 3.4 | X4: 3.5 | Y4: 1.1 | Z4: 2.1 | AA4: 2.1 | AB4: -2.5 | AC4: 1 | AD4: 5.6 | AE4: 6 | AF4: 4.8 | AG4: 3.2 | AH4: 1.5 | AI4: 5.4 | AJ4: 2 | AK4: -1 | AL4: 3.6 | AM4: 2.7 | AN4: 4.4 | AO4: 3.5 | AP4: 3.4 | AQ4: 4.1 | AR4: 3.5 | AS4: 2.4 | AT4: 1 | AU4: 0.1 | AV4: 5.1 | AW4: 3 | AX4: 3.2 | AY4: 2.7 | AZ4: 3.9 | BA4: 5.2 | BB4: -0.7 | BC4: 6.2 | BD4: 4 | BE4: 3.3 | BF4: 5.9 | BG4: 0.8 | BH4: 5.6 | BI4: 3.9 | BJ4: 2.6 | BK4: 3.1 | BL4: 4.7 | BM4: 7
A5: Duben | B5: 10.7 | C5: 8.6 | D5: 8.1 | E5: 8.3 | F5: 6.1 | G5: 9.1 | H5: 6.5 | I5: 8.5 | J5: 6.7 | K5: 5.7 | L5: 8 | M5: 6.7 | N5: 4.9 | O5: 7.2 | P5: 6.4 | Q5: 6.8 | R5: 5.4 | S5: 6.1 | T5: 5.9 | U5: 4.6 | V5: 6.6 | W5: 5.1 | X5: 9 | Y5: 6.4 | Z5: 7 | AA5: 8.3 | AB5: 7.9 | AC5: 7.5 | AD5: 8.1 | AE5: 6.5 | AF5: 6.3 | AG5: 7.3 | AH5: 9 | AI5: 7.5 | AJ5: 8 | AK5: 7.5 | AL5: 4.7 | AM5: 9.2 | AN5: 8.6 | AO5: 10.9 | AP5: 6.8 | AQ5: 7.5 | AR5: 7.1 | AS5: 8.7 | AT5: 8.9 | AU5: 8.1 | AV5: 10.3 | AW5: 7.8 | AX5: 12 | AY5: 8.1 | AZ5: 10.5 | BA5: 8.4 | BB5: 8.1 | BC5: 9.8 | BD5: 7.8 | BE5: 7.7 | BF5: 6.9 | BG5: 12.7 | BH5: 9.4 | BI5: 9.2 | BJ5: 5.4 | BK5: 6.4 | BL5: 6.4 | BM5: 10
A6: Květen | B6: 10.2 | C6: 9.7 | D6: 12 | E6: 12.8 | F6: 10.2 | G6: 12.4 | H6: 12.6 | I6: 11.2 | J6: 14.2 | K6: 10.6 | L6: 13.7 | M6: 11.7 | N6: 12.3 | O6: 10.9 | P6: 12.6 | Q6: 12.4 | R6: 11.9 | S6: 10.8 | T6: 13 | U6: 9.7 | V6: 12.9 | W6: 12.8 | X6: 12.9 | Y6: 11.3 | Z6: 13.5 | AA6: 14.5 | AB6: 10.3 | AC6: 13.9 | AD6: 12.8 | AE6: 13.3 | AF6: 8.9 | AG6: 13.6 | AH6: 15 | AI6: 12.4 | AJ6: 12.1 | AK6: 12.5 | AL6: 13.1 | AM6: 13.4 | AN6: 13.5 | AO6: 14.7 | AP6: 14.3 | AQ6: 15.4 | AR6: 15 | AS6: 11.3 | AT6: 13 | AU6: 12.7 | AV6: 14.4 | AW6: 13.6 | AX6: 13.3 | AY6: 11.5 | AZ6: 13.3 | BA6: 14.4 | BB6: 12 | BC6: 12.1 | BD6: 12.4 | BE6: 13.4 | BF6: 13.8 | BG6: 16.2 | BH6: 10.7 | BI6: 10.9 | BJ6: 10.6 | BK6: 14.3 | BL6: 12.6 | BM6: 14.5
A7: Červen | B7: 16.2 | C7: 13.8 | D7: 16 | E7: 17.5 | F7: 15.2 | G7: 16.2 | H7: 15 | I7: 16.2 | J7: 14.8 | K7: 16.3 | L7: 13.8 | M7: 15.5 | N7: 15.3 | O7: 13.4 | P7: 14.6 | Q7: 16.2 | R7: 16 | S7: 14.2 | T7: 17.6 | U7: 14.4 | V7: 16.1 | W7: 16.2 | X7: 15.9 | Y7: 13.8 | Z7: 13 | AA7: 15.4 | AB7: 14.6 | AC7: 15 | AD7: 14.4 | AE7: 15.4 | AF7: 14.3 | AG7: 17.1 | AH7: 15.4 | AI7: 16.3 | AJ7: 14.5 | AK7: 16 | AL7: 16.1 | AM7: 16.9 | AN7: 15.3 | AO7: 17.3 | AP7: 14.1 | AQ7: 17.4 | AR7: 19.4 | AS7: 15.3 | AT7: 16.1 | AU7: 16.9 | AV7: 18.1 | AW7: 17.4 | AX7: 14.9 | AY7: 16.6 | AZ7: 16.9 | BA7: 16.9 | BB7: 15.8 | BC7: 16 | BD7: 16.1 | BE7: 17.2 | BF7: 18.2 | BG7: 17.5 | BH7: 20.7 | BI7: 16.4 | BJ7: 18.8 | BK7: 18.7 | BL7: 17.2 | BM7: 17.9
A8: Červenec | B8: 15.2 | C8: 15.1 | D8: 18 | E8: 17.8 | F8: 15.5 | G8: 15.9 | H8: 18.5 | I8: 16.1 | J8: 17.9 | K8: 16.7 | L8: 17.7 | M8: 17.8 | N8: 16.6 | O8: 15.2 | P8: 17.6 | Q8: 18.4 | R8: 16.1 | S8: 15 | T8: 14.6 | U8: 14.7 | V8: 16.1 | W8: 18.2 | X8: 20 | Y8: 15.2 | Z8: 17.2 | AA8: 16.4 | AB8: 17.3 | AC8: 17.5 | AD8: 17.3 | AE8: 16.5 | AF8: 18.7 | AG8: 18.8 | AH8: 16.1 | AI8: 21 | AJ8: 20 | AK8: 15.6 | AL8: 16.5 | AM8: 17.1 | AN8: 18.6 | AO8: 15.4 | AP8: 17.9 | AQ8: 18.5 | AR8: 18.4 | AS8: 17.1 | AT8: 18 | AU8: 21.3 | AV8: 18.3 | AW8: 18 | AX8: 18.1 | AY8: 20 | AZ8: 16.3 | BA8: 18.2 | BB8: 19.4 | BC8: 19.2 | BD8: 20.2 | BE8: 18.6 | BF8: 18.5 | BG8: 19.7 | BH8: 18.8 | BI8: 17.7 | BJ8: 18.8 | BK8: 18.6 | BL8: 19.6 | BM8: 19.8
A9: Srpen | B9: 15.7 | C9: 16.7 | D9: 16.5 | E9: 15.1 | F9: 14.7 | G9: 15.3 | H9: 16.2 | I9: 15.7 | J9: 15.5 | K9: 16.3 | L9: 18.4 | M9: 15.7 | N9: 17.1 | O9: 17.7 | P9: 17.4 | Q9: 14.6 | R9: 15.6 | S9: 14.5 | T9: 15.5 | U9: 15.9 | V9: 16.3 | W9: 17.2 | X9: 17.5 | Y9: 16.3 | Z9: 16.5 | AA9: 16.4 | AB9: 14.8 | AC9: 16.8 | AD9: 16.7 | AE9: 17.9 | AF9: 17.1 | AG9: 20.8 | AH9: 16.6 | AI9: 18.1 | AJ9: 17.2 | AK9: 16.4 | AL9: 18.2 | AM9: 17.1 | AN9: 16.7 | AO9: 18.4 | AP9: 18.2 | AQ9: 18.5 | AR9: 20.1 | AS9: 18.1 | AT9: 15.8 | AU9: 15.1 | AV9: 17.7 | AW9: 17.5 | AX9: 18.4 | AY9: 17 | AZ9: 17.9 | BA9: 18.2 | BB9: 17.7 | BC9: 15.7 | BD9: 21.3 | BE9: 17 | BF9: 18.8 | BG9: 20.6 | BH9: 18.9 | BI9: 18.8 | BJ9: 16 | BK9: 19.1 | BL9: 18.6 | BM9: 20.2
A10: Září | B10: 15 | C10: 11.8 | D10: 13.8 | E10: 12.6 | F10: 12.7 | G10: 12.4 | H10: 13.8 | I10: 12.6 | J10: 13.1 | K10: 11.9 | L10: 10.7 | M10: 10.2 | N10: 13.7 | O10: 12.6 | P10: 15.5 | Q10: 11.7 | R10: 10.7 | S10: 11.5 | T10: 12.6 | U10: 12.2 | V10: 13.3 | W10: 15.4 | X10: 13.1 | Y10: 11.8 | Z10: 12.6 | AA10: 11.3 | AB10: 14.4 | AC10: 12.8 | AD10: 13.7 | AE10: 10.8 | AF10: 13.9 | AG10: 13.1 | AH10: 12 | AI10: 13.7 | AJ10: 11.9 | AK10: 9.7 | AL10: 12.7 | AM10: 12.4 | AN10: 16 | AO10: 12.6 | AP10: 11.1 | AQ10: 11.8 | AR10: 13.2 | AS10: 12.8 | AT10: 14.1 | AU10: 15.5 | AV10: 11.3 | AW10: 12 | AX10: 14.7 | AY10: 11.3 | AZ10: 14.6 | BA10: 13.2 | BB10: 11.8 | BC10: 14 | BD10: 13.1 | BE10: 15.8 | BF10: 11.8 | BG10: 14.5 | BH10: 13.3 | BI10: 14 | BJ10: 14.2 | BK10: 12 | BL10: 16.5 | BM10: 15
A11: Říjen | B11: 9.4 | C11: 7.5 | D11: 7.4 | E11: 6.7 | F11: 6.5 | G11: 11.3 | H11: 10.3 | I11: 8.4 | J11: 8.8 | K11: 7.4 | L11: 7.1 | M11: 5.3 | N11: 6 | O11: 4.4 | P11: 7.1 | Q11: 9 | R11: 8.8 | S11: 8.1 | T11: 6.6 | U11: 7 | V11: 8 | W11: 8.8 | X11: 8 | Y11: 9.1 | Z11: 7.4 | AA11: 8.1 | AB11: 8.5 | AC11: 8.5 | AD11: 9 | AE11: 8.5 | AF11: 6.8 | AG11: 6.2 | AH11: 7.7 | AI11: 6.1 | AJ11: 9.9 | AK11: 8.8 | AL11: 5.7 | AM11: 8.1 | AN11: 8 | AO11: 10.8 | AP11: 11.3 | AQ11: 6.8 | AR11: 4.9 | AS11: 9.2 | AT11: 9.1 | AU11: 10.1 | AV11: 7.2 | AW11: 8.3 | AX11: 7.2 | AY11: 6.1 | AZ11: 7.8 | BA11: 7.4 | BB11: 9 | BC11: 10 | BD11: 7.8 | BE11: 7.4 | BF11: 9.5 | BG11: 10 | BH11: 9.5 | BI11: 9 | BJ11: 8 | BK11: 10.7 | BL11: 11.1 | BM11: 9.8
A12: Listopad | B12: 2.7 | C12: 2.4 | D12: 6.4 | E12: 3.7 | F12: -0.3 | G12: 1.8 | H12: 2.6 | I12: 3.4 | J12: 4.2 | K12: 4.7 | L12: 2.1 | M12: 3.2 | N12: 1.1 | O12: 2.8 | P12: 1.3 | Q12: 4.1 | R12: 3.8 | S12: 1.9 | T12: 2.5 | U12: 1.3 | V12: 3 | W12: 3.8 | X12: 1.1 | Y12: 3.6 | Z12: -0.2 | AA12: 3.7 | AB12: 3.6 | AC12: -0.4 | AD12: 0.8 | AE12: 3.5 | AF12: 2.5 | AG12: 3.3 | AH12: -0.3 | AI12: 5 | AJ12: 0.3 | AK12: 4.3 | AL12: 2.7 | AM12: 0.1 | AN12: 1.6 | AO12: 5.4 | AP12: 1.5 | AQ12: 4.7 | AR12: 4.6 | AS12: 3.2 | AT12: 2 | AU12: 5.6 | AV12: 1.4 | AW12: 4.6 | AX12: 5.5 | AY12: 5 | AZ12: 2.5 | BA12: 4.8 | BB12: 4.1 | BC12: 6 | BD12: 5.7 | BE12: 2.7 | BF12: 3.7 | BG12: 4.3 | BH12: 5.6 | BI12: 3.9 | BJ12: 3.6 | BK12: 4.1 | BL12: 4.1 | BM12: 2.8
A13: Prosinec | B13: -3.2 | C13: -5.5 | D13: -5.6 | E13: -1.7 | F13: 0.7 | G13: -0.1 | H13: -1.5 | I13: -3.7 | J13: -6.3 | K13: -1.1 | L13: 2.1 | M13: -1.3 | N13: -1.5 | O13: 2.6 | P13: -0.6 | Q13: -2.4 | R13: -1.2 | S13: -0.8 | T13: 2.6 | U13: -1.3 | V13: -3.3 | W13: 0.7 | X13: -1.5 | Y13: -1.2 | Z13: 2 | AA13: -0.8 | AB13: 0.3 | AC13: 0.8 | AD13: 0.1 | AE13: -1.3 | AF13: -2.3 | AG13: -1.5 | AH13: 1.5 | AI13: 0.9 | AJ13: -2.7 | AK13: -5.1 | AL13: 0.7 | AM13: -1.9 | AN13: -0.4 | AO13: 0.6 | AP13: -3.6 | AQ13: -2.8 | AR13: -0.6 | AS13: -0.7 | AT13: -1.3 | AU13: 2.3 | AV13: -0.9 | AW13: 0.7 | AX13: -1 | AY13: -4.9 | AZ13: 1.9 | BA13: -1.4 | BB13: 1.2 | BC13: 1.6 | BD13: 3.7 | BE13: -0.5 | BF13: 0.8 | BG13: 1.2 | BH13: 1.9 | BI13: 1.7 | BJ13: 0.4 | BK13: 0.3 | BL13: 2.4 | BM13: 0.9
A14: Roční průměr | B14: 7.9 | C14: 6.3 | D14: 6.5 | E14: 6.9 | F14: 6.4 | G14: 7.9 | H14: 8 | I14: 7.3 | J14: 6.9 | K14: 6.9 | L14: 7.5 | M14: 7.2 | N14: 7.2 | O14: 7.9 | P14: 8 | Q14: 7.3 | R14: 7.6 | S14: 6.8 | T14: 7.2 | U14: 6.3 | V14: 7.4 | W14: 7.8 | X14: 8.2 | Y14: 7 | Z14: 6.5 | AA14: 7.2 | AB14: 6.6 | AC14: 7.9 | AD14: 8.4 | AE14: 8.4 | AF14: 7.2 | AG14: 8.6 | AH14: 7.6 | AI14: 8.9 | AJ14: 7.9 | AK14: 6.3 | AL14: 7.6 | AM14: 8.2 | AN14: 8.4 | AO14: 9.1 | AP14: 7.8 | AQ14: 8.7 | AR14: 8.2 | AS14: 7.8 | AT14: 7.7 | AU14: 8.2 | AV14: 9.1 | AW14: 8.9 | AX14: 8.4 | AY14: 7.2 | AZ14: 8.5 | BA14: 8.3 | BB14: 7.9 | BC14: 9.4 | BD14: 9.4 | BE14: 8.7 | BF14: 8.6 | BG14: 9.6 | BH14: 9.5 | BI14: 9.1 | BJ14: 8 | BK14: 9.2 | BL14: 9.7 | BM14: 10.3

Sheet Předběžná teplota 2025 Shrnutí
B1: Teplota ČR od roku 1961
B2: adresa | C2: verze | D2: autor | E2: licence
B3: https://faktaoklimatu.cz/infografiky/teplota-cr https://faktaoklimatu.cz/infografiky/teplota-cr-mesice https://faktaoklimatu.cz/infografiky/trend-teplot-cr | C3: 45662 | D3: Fakta o klimatu | E3: CC BY 4.0
B4: =IF(ISERR(FIND("neaktuální", C2)), "", "Toto je neaktuální verze datasetu. Aktuální verzi naleznete na stránce výše.")
B5: Historie změn
B6: 45662 | C6: Aktualizace průměrných teplot za rok 2024 podle dat z tiskové zprávy ČHMÚ
B7: 45295 | C7: Aktualizace průměrných teplot za rok 2023 podle dat z tiskové zprávy ČHMÚ
B8: 45162 | C8: Aktualizace průměrných teplot za rok 2022 podle dat ČHMÚ
B9: 43904 | C9: Aktualizace průměrných teplot za rok 2021 podle dat ČHMÚ
B10: 44572 | C10: Aktualizace za rok 2021
B11: 44254 | C11: Aktualizace za rok 2020
B12: 43866 | C12: První verze datasetu
A14: A | B14: VSTUPY
B15: Údaj | C15: Zdroj | D15: Hodnota | E15: Datum stažení | F15: Komentář | I15: Odkaz
A17: 1 | B17: Měsíční teploty v ČR
B18: Měsíční teploty v ČR | C18: ČHMÚ | D18: Tabulka v příloze | E18: 45662 | F18: Data ručně vykopírována z jednotlivých let. Na zdrojových stránkách jsou v odkazech pro jednotlivé roky uvedené průměrné teploty vzduchu [°C] v daném měsíci, uspořádané podle měsíců (v daném roce) a podle krajů. Vzhledem k velikosti ČR nebudou v trendech pro jednotlivé kraje podstatné rozdíly, proto dále pracujeme pouze s průměrnými teplotami pro daný rok a měsíc v rámci celé ČR. | I18: http://portal.chmi.cz/historicka-data/pocasi/uzemni-teploty
A20: B | B20: VÝSTUPY
A22: 3 | B22: Lineární trend
B23: Sklon lineárního trendu teplot ČR | D23: {=TRANSPOSE(LINEST(C29:C93))} -> 0.03631993 | F23: Spočítáno metodou nejmenších čtverců.
B24: Hodnota lineárního trendu teplot ČR pro první rok (1961) | D24: 6.7429808 | F24: Spočítáno metodou nejmenších čtverců.
A26: 4 | B26: Průměrné roční teploty v ČR
B28: Rok | C28: Průměrná teplota | D28: Klouzavý průměr 5 let | E28: Lineární trend
B29: ='Vstup Měsíční teploty ČR'!$A4 -> 1961 | C29: ='Vstup Měsíční teploty ČR'!$N4 -> 7.9 | D29: není k dispozici | E29: =$D$24+$D$23*($B29-1961) -> 6.7429808
B30: ='Vstup Měsíční teploty ČR'!A5 -> 1962 | C30: ='Vstup Měsíční teploty ČR'!$N5 -> 6.3 | D30: není k dispozici | E30: =$D$24+$D$23*($B30-1961) -> 6.7793007
B31: ='Vstup Měsíční teploty ČR'!A6 -> 1963 | C31: ='Vstup Měsíční teploty ČR'!$N6 -> 6.5 | D31: =AVERAGE(C29:C33) -> 6.8 | E31: =$D$24+$D$23*($B31-1961) -> 6.8156206
B32: ='Vstup Měsíční teploty ČR'!A7 -> 1964 | C32: ='Vstup Měsíční teploty ČR'!$N7 -> 6.9 | D32: =AVERAGE(C30:C34) -> 6.8 | E32: =$D$24+$D$23*($B32-1961) -> 6.8519406
B33: ='Vstup Měsíční teploty ČR'!A8 -> 1965 | C33: ='Vstup Měsíční teploty ČR'!$N8 -> 6.4 | D33: =AVERAGE(C31:C35) -> 7.14 | E33: =$D$24+$D$23*($B33-1961) -> 6.8882605
B34: ='Vstup Měsíční teploty ČR'!A9 -> 1966 | C34: ='Vstup Měsíční teploty ČR'!$N9 -> 7.9 | D34: =AVERAGE(C32:C36) -> 7.3 | E34: =$D$24+$D$23*($B34-1961) -> 6.9245804
B35: ='Vstup Měsíční teploty ČR'!A10 -> 1967 | C35: ='Vstup Měsíční teploty ČR'!$N10 -> 8 | D35: =AVERAGE(C33:C37) -> 7.3 | E35: =$D$24+$D$23*($B35-1961) -> 6.9609004
B36: ='Vstup Měsíční teploty ČR'!A11 -> 1968 | C36: ='Vstup Měsíční teploty ČR'!$N11 -> 7.3 | D36: =AVERAGE(C34:C38) -> 7.4 | E36: =$D$24+$D$23*($B36-1961) -> 6.9972203
B37: ='Vstup Měsíční teploty ČR'!A12 -> 1969 | C37: ='Vstup Měsíční teploty ČR'!$N12 -> 6.9 | D37: =AVERAGE(C35:C39) -> 7.32 | E37: =$D$24+$D$23*($B37-1961) -> 7.0335402
B38: ='Vstup Měsíční teploty ČR'!A13 -> 1970 | C38: ='Vstup Měsíční teploty ČR'!$N13 -> 6.9 | D38: =AVERAGE(C36:C40) -> 7.16 | E38: =$D$24+$D$23*($B38-1961) -> 7.0698601
B39: ='Vstup Měsíční teploty ČR'!A14 -> 1971 | C39: ='Vstup Měsíční teploty ČR'!$N14 -> 7.5 | D39: =AVERAGE(C37:C41) -> 7.14 | E39: =$D$24+$D$23*($B39-1961) -> 7.1061801
B40: ='Vstup Měsíční teploty ČR'!A15 -> 1972 | C40: ='Vstup Měsíční teploty ČR'!$N15 -> 7.2 | D40: =AVERAGE(C38:C42) -> 7.34 | E40: =$D$24+$D$23*($B40-1961) -> 7.1425
B41: ='Vstup Měsíční teploty ČR'!A16 -> 1973 | C41: ='Vstup Měsíční teploty ČR'!$N16 -> 7.2 | D41: =AVERAGE(C39:C43) -> 7.56 | E41: =$D$24+$D$23*($B41-1961) -> 7.1788199
B42: ='Vstup Měsíční teploty ČR'!A17 -> 1974 | C42: ='Vstup Měsíční teploty ČR'!$N17 -> 7.9 | D42: =AVERAGE(C40:C44) -> 7.52 | E42: =$D$24+$D$23*($B42-1961) -> 7.2151399
... B87: ='Vstup Měsíční teploty ČR'!A62 -> 2019 | C87: ='Vstup Měsíční teploty ČR'!$N62 -> 9.5 | D87: =AVERAGE(C85:C89) -> 8.96 | E87: =$D$24+$D$23*($B87-1961) -> 8.8495367
B88: 2020 | C88: ='Vstup Měsíční teploty ČR'!$N63 -> 9.1 | D88: =AVERAGE(C86:C90) -> 9.08 | E88: =$D$24+$D$23*($B88-1961) -> 8.8858566
B89: 2021 | C89: ='Vstup Měsíční teploty ČR'!$N64 -> 8 | D89: =AVERAGE(C87:C91) -> 9.1 | E89: =$D$24+$D$23*($B89-1961) -> 8.9221766
B90: 2022 | C90: ='Vstup Měsíční teploty ČR'!$N65 -> 9.2 | D90: =AVERAGE(C88:C92) -> 9.26 | E90: =$D$24+$D$23*($B90-1961) -> 8.9584965
...

Sheet Výstup p-hodnoty
A1: R skript | B1: # Načti tabulku dat: Vstup: Měsíční hodnoty ČR Temp_CR <- read.csv("Teploty_CR.csv", header = T, sep = ";", dec = ".") vysledky <- data.frame("obdobi" = c("Leden", "Únor", "Březen", "Duben", "Květen", "Červen", "Červenec", "Srpen", "Září", "Říjen", "Listopad", "Prosinec", "Roční průměr"), "p" = rep(NA, 13)) for(sloupec in 2:ncol(Temp_CR)) { vysledky$p[sloupec-1] <- round(as.numeric(cor.test(Temp_CR[, 1], Temp_CR[, sloupec], alternative = "two.sided", type="pearson", conf.level = 0.95)[3]), digits = 5) } # Vypiš výsednou tabulku, viz tabulka níže write.table(vysledky, file = "vysledky.csv", sep = ";", dec = ".", row.names = F)
A2: obdobi | B2: p
A3: Leden | B3: 0.034
A4: Únor | B4: 0.27
A5: Březen | B5: 0.045
A6: Duben | B6: 0.002
A7: Květen | B7: 0.001
A8: Červen | B8: 0
A9: Červenec | B9: 5e-05
A10: Srpen | B10: 1e-05
A11: Září | B11: 0.27
A12: Říjen | B12: 0.21
A13: Listopad | B13: 0.023
A14: Prosinec | B14: 0.006
A15: Roční průměr | B15: 0
